Workbook

Sheet Sales Dashboard
B2: AUTOMOTIVE INVENTORY · SALES DASHBOARD
B3: Sold vehicles · updates automatically from the Data tab
B5: UNITS SOLD | D5: TOTAL PROFIT | F5: TOTAL SALES (CUMULATIVE)
B6: =COUNTIF(Data!$F$2:$F$60,"Sold") -> 25 | D6: =SUM(Data!$I$2:$I$60) -> 25025 | F6: =SUM(Data!$H$2:$H$60) -> 114525
B9: OVERALL ROI | D9: AVG PROFIT / SALE | F9: AVG DAYS TO SELL
B10: =IFERROR(SUM(Data!$I$2:$I$60)/SUMIF(Data!$F$2:$F$60,"Sold",Data!$G$2:$G$60),0) -> 0.27960894 | D10: =IFERROR(AVERAGE(Data!$I$2:$I$60),0) -> 1001 | F10: =IFERROR(AVERAGE(Data!$J$2:$J$60),0) -> 14.68
B14: MONTHLY PROFIT (newest first) | F14: PROFIT BY MAKE | J14: MOST-SOLD MODELS · FASTEST FIRST
B15: Month | C15: Units | D15: Profit | F15: Make | G15: Units | H15: Profit | J15: Model | K15: Sold | L15: Avg Days | M15: Avg Profit
B16: 05/2026 | C16: =COUNTIF(Data!$U$2:$U$60,"2026-05") -> 1 | D16: =SUMIF(Data!$U$2:$U$60,"2026-05",Data!$I$2:$I$60) -> 900 | F16: CFMoto | G16: =COUNTIFS(Data!$F$2:$F$60,"Sold",Data!$B$2:$B$60,$F16) -> 1 | H16: =SUMIF(Data!$B$2:$B$60,$F16,Data!$I$2:$I$60) -> 800 | J16: Kawasaki Ninja 400 | K16: =COUNTIFS(Data!$F$2:$F$60,"Sold",Data!$B$2:$B$60,"Kawasaki",Data!$C$2:$C$60,"Ninja 400") -> 6 | L16: =IFERROR(AVERAGEIFS(Data!$J$2:$J$60,Data!$F$2:$F$60,"Sold",Data!$B$2:$B$60,"Kawasaki",Data!$C$2:$C$60,"Ninja 400"),"") -> 10.833333 | M16: =IFERROR(AVERAGEIFS(Data!$I$2:$I$60,Data!$F$2:$F$60,"Sold",Data!$B$2:$B$60,"Kawasaki",Data!$C$2:$C$60,"Ninja 400"),"") -> 1066.6667
B17: 04/2026 | C17: =COUNTIF(Data!$U$2:$U$60,"2026-04") -> 3 | D17: =SUMIF(Data!$U$2:$U$60,"2026-04",Data!$I$2:$I$60) -> 2700 | F17: Ducati | G17: =COUNTIFS(Data!$F$2:$F$60,"Sold",Data!$B$2:$B$60,$F17) -> 1 | H17: =SUMIF(Data!$B$2:$B$60,$F17,Data!$I$2:$I$60) -> 200 | J17: Kawasaki Ninja 500 | K17: =COUNTIFS(Data!$F$2:$F$60,"Sold",Data!$B$2:$B$60,"Kawasaki",Data!$C$2:$C$60,"Ninja 500") -> 3 | L17: =IFERROR(AVERAGEIFS(Data!$J$2:$J$60,Data!$F$2:$F$60,"Sold",Data!$B$2:$B$60,"Kawasaki",Data!$C$2:$C$60,"Ninja 500"),"") -> 11 | M17: =IFERROR(AVERAGEIFS(Data!$I$2:$I$60,Data!$F$2:$F$60,"Sold",Data!$B$2:$B$60,"Kawasaki",Data!$C$2:$C$60,"Ninja 500"),"") -> 733.33333
B18: 03/2026 | C18: =COUNTIF(Data!$U$2:$U$60,"2026-03") -> 4 | D18: =SUMIF(Data!$U$2:$U$60,"2026-03",Data!$I$2:$I$60) -> 3450 | F18: Honda | G18: =COUNTIFS(Data!$F$2:$F$60,"Sold",Data!$B$2:$B$60,$F18) -> 1 | H18: =SUMIF(Data!$B$2:$B$60,$F18,Data!$I$2:$I$60) -> 500 | J18: Yamaha YZF-R3 | K18: =COUNTIFS(Data!$F$2:$F$60,"Sold",Data!$B$2:$B$60,"Yamaha",Data!$C$2:$C$60,"YZF-R3") -> 3 | L18: =IFERROR(AVERAGEIFS(Data!$J$2:$J$60,Data!$F$2:$F$60,"Sold",Data!$B$2:$B$60,"Yamaha",Data!$C$2:$C$60,"YZF-R3"),"") -> 14.333333 | M18: =IFERROR(AVERAGEIFS(Data!$I$2:$I$60,Data!$F$2:$F$60,"Sold",Data!$B$2:$B$60,"Yamaha",Data!$C$2:$C$60,"YZF-R3"),"") -> 1066.6667
B19: 02/2026 | C19: =COUNTIF(Data!$U$2:$U$60,"2026-02") -> 1 | D19: =SUMIF(Data!$U$2:$U$60,"2026-02",Data!$I$2:$I$60) -> 500 | F19: KTM | G19: =COUNTIFS(Data!$F$2:$F$60,"Sold",Data!$B$2:$B$60,$F19) -> 1 | H19: =SUMIF(Data!$B$2:$B$60,$F19,Data!$I$2:$I$60) -> 1750 | J19: Kawasaki Ninja 300 | K19: =COUNTIFS(Data!$F$2:$F$60,"Sold",Data!$B$2:$B$60,"Kawasaki",Data!$C$2:$C$60,"Ninja 300") -> 2 | L19: =IFERROR(AVERAGEIFS(Data!$J$2:$J$60,Data!$F$2:$F$60,"Sold",Data!$B$2:$B$60,"Kawasaki",Data!$C$2:$C$60,"Ninja 300"),"") -> 12 | M19: =IFERROR(AVERAGEIFS(Data!$I$2:$I$60,Data!$F$2:$F$60,"Sold",Data!$B$2:$B$60,"Kawasaki",Data!$C$2:$C$60,"Ninja 300"),"") -> 1050
B20: 11/2025 | C20: =COUNTIF(Data!$U$2:$U$60,"2025-11") -> 2 | D20: =SUMIF(Data!$U$2:$U$60,"2025-11",Data!$I$2:$I$60) -> 950 | F20: Kawasaki | G20: =COUNTIFS(Data!$F$2:$F$60,"Sold",Data!$B$2:$B$60,$F20) -> 16 | H20: =SUMIF(Data!$B$2:$B$60,$F20,Data!$I$2:$I$60) -> 16225 | J20: Kawasaki Ninja 650 | K20: =COUNTIFS(Data!$F$2:$F$60,"Sold",Data!$B$2:$B$60,"Kawasaki",Data!$C$2:$C$60,"Ninja 650") -> 2 | L20: =IFERROR(AVERAGEIFS(Data!$J$2:$J$60,Data!$F$2:$F$60,"Sold",Data!$B$2:$B$60,"Kawasaki",Data!$C$2:$C$60,"Ninja 650"),"") -> 16 | M20: =IFERROR(AVERAGEIFS(Data!$I$2:$I$60,Data!$F$2:$F$60,"Sold",Data!$B$2:$B$60,"Kawasaki",Data!$C$2:$C$60,"Ninja 650"),"") -> 1462.5
B21: 10/2025 | C21: =COUNTIF(Data!$U$2:$U$60,"2025-10") -> 1 | D21: =SUMIF(Data!$U$2:$U$60,"2025-10",Data!$I$2:$I$60) -> 900 | F21: Toyota | G21: =COUNTIFS(Data!$F$2:$F$60,"Sold",Data!$B$2:$B$60,$F21) -> 2 | H21: =SUMIF(Data!$B$2:$B$60,$F21,Data!$I$2:$I$60) -> 2350 | J21: Toyota Camry | K21: =COUNTIFS(Data!$F$2:$F$60,"Sold",Data!$B$2:$B$60,"Toyota",Data!$C$2:$C$60,"Camry") -> 2 | L21: =IFERROR(AVERAGEIFS(Data!$J$2:$J$60,Data!$F$2:$F$60,"Sold",Data!$B$2:$B$60,"Toyota",Data!$C$2:$C$60,"Camry"),"") -> 18.5 | M21: =IFERROR(AVERAGEIFS(Data!$I$2:$I$60,Data!$F$2:$F$60,"Sold",Data!$B$2:$B$60,"Toyota",Data!$C$2:$C$60,"Camry"),"") -> 1175
B22: 09/2025 | C22: =COUNTIF(Data!$U$2:$U$60,"2025-09") -> 5 | D22: =SUMIF(Data!$U$2:$U$60,"2025-09",Data!$I$2:$I$60) -> 5200 | F22: Yamaha | G22: =COUNTIFS(Data!$F$2:$F$60,"Sold",Data!$B$2:$B$60,$F22) -> 3 | H22: =SUMIF(Data!$B$2:$B$60,$F22,Data!$I$2:$I$60) -> 3200 | J22: Kawasaki Ninja 250 | K22: =COUNTIFS(Data!$F$2:$F$60,"Sold",Data!$B$2:$B$60,"Kawasaki",Data!$C$2:$C$60,"Ninja 250") -> 1 | L22: =IFERROR(AVERAGEIFS(Data!$J$2:$J$60,Data!$F$2:$F$60,"Sold",Data!$B$2:$B$60,"Kawasaki",Data!$C$2:$C$60,"Ninja 250"),"") -> 12 | M22: =IFERROR(AVERAGEIFS(Data!$I$2:$I$60,Data!$F$2:$F$60,"Sold",Data!$B$2:$B$60,"Kawasaki",Data!$C$2:$C$60,"Ninja 250"),"") -> 900
B23: 08/2025 | C23: =COUNTIF(Data!$U$2:$U$60,"2025-08") -> 6 | D23: =SUMIF(Data!$U$2:$U$60,"2025-08",Data!$I$2:$I$60) -> 7775 | J23: CFMoto 300SS | K23: =COUNTIFS(Data!$F$2:$F$60,"Sold",Data!$B$2:$B$60,"CFMoto",Data!$C$2:$C$60,"300SS") -> 1 | L23: =IFERROR(AVERAGEIFS(Data!$J$2:$J$60,Data!$F$2:$F$60,"Sold",Data!$B$2:$B$60,"CFMoto",Data!$C$2:$C$60,"300SS"),"") -> 13 | M23: =IFERROR(AVERAGEIFS(Data!$I$2:$I$60,Data!$F$2:$F$60,"Sold",Data!$B$2:$B$60,"CFMoto",Data!$C$2:$C$60,"300SS"),"") -> 800
B24: 07/2025 | C24: =COUNTIF(Data!$U$2:$U$60,"2025-07") -> 2 | D24: =SUMIF(Data!$U$2:$U$60,"2025-07",Data!$I$2:$I$60) -> 2650 | J24: Kawasaki ZX-6R | K24: =COUNTIFS(Data!$F$2:$F$60,"Sold",Data!$B$2:$B$60,"Kawasaki",Data!$C$2:$C$60,"ZX-6R") -> 1 | L24: =IFERROR(AVERAGEIFS(Data!$J$2:$J$60,Data!$F$2:$F$60,"Sold",Data!$B$2:$B$60,"Kawasaki",Data!$C$2:$C$60,"ZX-6R"),"") -> 18 | M24: =IFERROR(AVERAGEIFS(Data!$I$2:$I$60,Data!$F$2:$F$60,"Sold",Data!$B$2:$B$60,"Kawasaki",Data!$C$2:$C$60,"ZX-6R"),"") -> 900
B25: TOTAL | C25: =SUM(C16:C24) -> 25 | D25: =SUM(D16:D24) -> 25025 | J25: KTM Duke 390 | K25: =COUNTIFS(Data!$F$2:$F$60,"Sold",Data!$B$2:$B$60,"KTM",Data!$C$2:$C$60,"Duke 390") -> 1 | L25: =IFERROR(AVERAGEIFS(Data!$J$2:$J$60,Data!$F$2:$F$60,"Sold",Data!$B$2:$B$60,"KTM",Data!$C$2:$C$60,"Duke 390"),"") -> 19 | M25: =IFERROR(AVERAGEIFS(Data!$I$2:$I$60,Data!$F$2:$F$60,"Sold",Data!$B$2:$B$60,"KTM",Data!$C$2:$C$60,"Duke 390"),"") -> 1750
J26: Kawasaki Z500 | K26: =COUNTIFS(Data!$F$2:$F$60,"Sold",Data!$B$2:$B$60,"Kawasaki",Data!$C$2:$C$60,"Z500") -> 1 | L26: =IFERROR(AVERAGEIFS(Data!$J$2:$J$60,Data!$F$2:$F$60,"Sold",Data!$B$2:$B$60,"Kawasaki",Data!$C$2:$C$60,"Z500"),"") -> 21 | M26: =IFERROR(AVERAGEIFS(Data!$I$2:$I$60,Data!$F$2:$F$60,"Sold",Data!$B$2:$B$60,"Kawasaki",Data!$C$2:$C$60,"Z500"),"") -> 800
J27: Honda CBR500R | K27: =COUNTIFS(Data!$F$2:$F$60,"Sold",Data!$B$2:$B$60,"Honda",Data!$C$2:$C$60,"CBR500R") -> 1 | L27: =IFERROR(AVERAGEIFS(Data!$J$2:$J$60,Data!$F$2:$F$60,"Sold",Data!$B$2:$B$60,"Honda",Data!$C$2:$C$60,"CBR500R"),"") -> 22 | M27: =IFERROR(AVERAGEIFS(Data!$I$2:$I$60,Data!$F$2:$F$60,"Sold",Data!$B$2:$B$60,"Honda",Data!$C$2:$C$60,"CBR500R"),"") -> 500
J28: Ducati Monster 696 | K28: =COUNTIFS(Data!$F$2:$F$60,"Sold",Data!$B$2:$B$60,"Ducati",Data!$C$2:$C$60,"Monster 696") -> 1 | L28: =IFERROR(AVERAGEIFS(Data!$J$2:$J$60,Data!$F$2:$F$60,"Sold",Data!$B$2:$B$60,"Ducati",Data!$C$2:$C$60,"Monster 696"),"") -> 28 | M28: =IFERROR(AVERAGEIFS(Data!$I$2:$I$60,Data!$F$2:$F$60,"Sold",Data!$B$2:$B$60,"Ducati",Data!$C$2:$C$60,"Monster 696"),"") -> 200

Sheet Inventory Dashboard
B2: AUTOMOTIVE INVENTORY · INVENTORY DASHBOARD
B3: Vehicles you currently hold · updates automatically
B5: UNITS IN INVENTORY | D5: CAPITAL TIED UP | F5: AVG DAYS HELD
B6: =COUNTIF(Data!$F$2:$F$60,"In Inventory") -> 5 | D6: =SUMIF(Data!$F$2:$F$60,"In Inventory",Data!$G$2:$G$60) -> 15400 | F6: =IFERROR(AVERAGEIF(Data!$F$2:$F$60,"In Inventory",Data!$V$2:$V$60),0) -> 80
B10: CURRENT INVENTORY (newest first)
B11: Purchased | C11: Year | D11: Make | E11: Model | F11: Buy Price | G11: Days Held | H11: Partners
B12: =IFERROR(INDEX(Data!$K$2:$K$60,MATCH(1,Data!$W$2:$W$60,0)),"") -> 46176 | C12: =IFERROR(INDEX(Data!$D$2:$D$60,MATCH(1,Data!$W$2:$W$60,0)),"") -> 2014 | D12: =IFERROR(INDEX(Data!$B$2:$B$60,MATCH(1,Data!$W$2:$W$60,0)),"") -> Kawasaki | E12: =IFERROR(INDEX(Data!$C$2:$C$60,MATCH(1,Data!$W$2:$W$60,0)),"") -> Ninja 300 | F12: =IFERROR(INDEX(Data!$G$2:$G$60,MATCH(1,Data!$W$2:$W$60,0)),"") -> 2500 | G12: =IFERROR(INDEX(Data!$V$2:$V$60,MATCH(1,Data!$W$2:$W$60,0)),"") -> 9 | H12: =IFERROR(INDEX(Data!$O$2:$O$60,MATCH(1,Data!$W$2:$W$60,0))&" / "&INDEX(Data!$R$2:$R$60,MATCH(1,Data!$W$2:$W$60,0)),"") -> Zeshan / Asmaar
B13: =IFERROR(INDEX(Data!$K$2:$K$60,MATCH(2,Data!$W$2:$W$60,0)),"") -> 46158 | C13: =IFERROR(INDEX(Data!$D$2:$D$60,MATCH(2,Data!$W$2:$W$60,0)),"") -> 2015 | D13: =IFERROR(INDEX(Data!$B$2:$B$60,MATCH(2,Data!$W$2:$W$60,0)),"") -> Kawasaki | E13: =IFERROR(INDEX(Data!$C$2:$C$60,MATCH(2,Data!$W$2:$W$60,0)),"") -> Ninja 300 | F13: =IFERROR(INDEX(Data!$G$2:$G$60,MATCH(2,Data!$W$2:$W$60,0)),"") -> 2400 | G13: =IFERROR(INDEX(Data!$V$2:$V$60,MATCH(2,Data!$W$2:$W$60,0)),"") -> 27 | H13: =IFERROR(INDEX(Data!$O$2:$O$60,MATCH(2,Data!$W$2:$W$60,0))&" / "&INDEX(Data!$R$2:$R$60,MATCH(2,Data!$W$2:$W$60,0)),"") -> Zeshan / Asmaar
B14: =IFERROR(INDEX(Data!$K$2:$K$60,MATCH(3,Data!$W$2:$W$60,0)),"") -> 46151 | C14: =IFERROR(INDEX(Data!$D$2:$D$60,MATCH(3,Data!$W$2:$W$60,0)),"") -> 2021 | D14: =IFERROR(INDEX(Data!$B$2:$B$60,MATCH(3,Data!$W$2:$W$60,0)),"") -> Kawasaki | E14: =IFERROR(INDEX(Data!$C$2:$C$60,MATCH(3,Data!$W$2:$W$60,0)),"") -> Ninja 650 | F14: =IFERROR(INDEX(Data!$G$2:$G$60,MATCH(3,Data!$W$2:$W$60,0)),"") -> 4800 | G14: =IFERROR(INDEX(Data!$V$2:$V$60,MATCH(3,Data!$W$2:$W$60,0)),"") -> 34 | H14: =IFERROR(INDEX(Data!$O$2:$O$60,MATCH(3,Data!$W$2:$W$60,0))&" / "&INDEX(Data!$R$2:$R$60,MATCH(3,Data!$W$2:$W$60,0)),"") -> Zeshan / Asmaar
B15: =IFERROR(INDEX(Data!$K$2:$K$60,MATCH(4,Data!$W$2:$W$60,0)),"") -> 46132 | C15: =IFERROR(INDEX(Data!$D$2:$D$60,MATCH(4,Data!$W$2:$W$60,0)),"") -> 2015 | D15: =IFERROR(INDEX(Data!$B$2:$B$60,MATCH(4,Data!$W$2:$W$60,0)),"") -> Yamaha | E15: =IFERROR(INDEX(Data!$C$2:$C$60,MATCH(4,Data!$W$2:$W$60,0)),"") -> YZF-R3 | F15: =IFERROR(INDEX(Data!$G$2:$G$60,MATCH(4,Data!$W$2:$W$60,0)),"") -> 2500 | G15: =IFERROR(INDEX(Data!$V$2:$V$60,MATCH(4,Data!$W$2:$W$60,0)),"") -> 53 | H15: =IFERROR(INDEX(Data!$O$2:$O$60,MATCH(4,Data!$W$2:$W$60,0))&" / "&INDEX(Data!$R$2:$R$60,MATCH(4,Data!$W$2:$W$60,0)),"") -> Zeshan / Asmaar
B16: =IFERROR(INDEX(Data!$K$2:$K$60,MATCH(5,Data!$W$2:$W$60,0)),"") -> 45908 | C16: =IFERROR(INDEX(Data!$D$2:$D$60,MATCH(5,Data!$W$2:$W$60,0)),"") -> 2009 | D16: =IFERROR(INDEX(Data!$B$2:$B$60,MATCH(5,Data!$W$2:$W$60,0)),"") -> Toyota | E16: =IFERROR(INDEX(Data!$C$2:$C$60,MATCH(5,Data!$W$2:$W$60,0)),"") -> Camry | F16: =IFERROR(INDEX(Data!$G$2:$G$60,MATCH(5,Data!$W$2:$W$60,0)),"") -> 3200 | G16: =IFERROR(INDEX(Data!$V$2:$V$60,MATCH(5,Data!$W$2:$W$60,0)),"") -> 277 | H16: =IFERROR(INDEX(Data!$O$2:$O$60,MATCH(5,Data!$W$2:$W$60,0))&" / "&INDEX(Data!$R$2:$R$60,MATCH(5,Data!$W$2:$W$60,0)),"") -> Zeshan / Asmaar
B17: =IFERROR(INDEX(Data!$K$2:$K$60,MATCH(6,Data!$W$2:$W$60,0)),"") | C17: =IFERROR(INDEX(Data!$D$2:$D$60,MATCH(6,Data!$W$2:$W$60,0)),"") | D17: =IFERROR(INDEX(Data!$B$2:$B$60,MATCH(6,Data!$W$2:$W$60,0)),"") | E17: =IFERROR(INDEX(Data!$C$2:$C$60,MATCH(6,Data!$W$2:$W$60,0)),"") | F17: =IFERROR(INDEX(Data!$G$2:$G$60,MATCH(6,Data!$W$2:$W$60,0)),"") | G17: =IFERROR(INDEX(Data!$V$2:$V$60,MATCH(6,Data!$W$2:$W$60,0)),"") | H17: =IFERROR(INDEX(Data!$O$2:$O$60,MATCH(6,Data!$W$2:$W$60,0))&" / "&INDEX(Data!$R$2:$R$60,MATCH(6,Data!$W$2:$W$60,0)),"")
B18: =IFERROR(INDEX(Data!$K$2:$K$60,MATCH(7,Data!$W$2:$W$60,0)),"") | C18: =IFERROR(INDEX(Data!$D$2:$D$60,MATCH(7,Data!$W$2:$W$60,0)),"") | D18: =IFERROR(INDEX(Data!$B$2:$B$60,MATCH(7,Data!$W$2:$W$60,0)),"") | E18: =IFERROR(INDEX(Data!$C$2:$C$60,MATCH(7,Data!$W$2:$W$60,0)),"") | F18: =IFERROR(INDEX(Data!$G$2:$G$60,MATCH(7,Data!$W$2:$W$60,0)),"") | G18: =IFERROR(INDEX(Data!$V$2:$V$60,MATCH(7,Data!$W$2:$W$60,0)),"") | H18: =IFERROR(INDEX(Data!$O$2:$O$60,MATCH(7,Data!$W$2:$W$60,0))&" / "&INDEX(Data!$R$2:$R$60,MATCH(7,Data!$W$2:$W$60,0)),"")
B19: =IFERROR(INDEX(Data!$K$2:$K$60,MATCH(8,Data!$W$2:$W$60,0)),"") | C19: =IFERROR(INDEX(Data!$D$2:$D$60,MATCH(8,Data!$W$2:$W$60,0)),"") | D19: =IFERROR(INDEX(Data!$B$2:$B$60,MATCH(8,Data!$W$2:$W$60,0)),"") | E19: =IFERROR(INDEX(Data!$C$2:$C$60,MATCH(8,Data!$W$2:$W$60,0)),"") | F19: =IFERROR(INDEX(Data!$G$2:$G$60,MATCH(8,Data!$W$2:$W$60,0)),"") | G19: =IFERROR(INDEX(Data!$V$2:$V$60,MATCH(8,Data!$W$2:$W$60,0)),"") | H19: =IFERROR(INDEX(Data!$O$2:$O$60,MATCH(8,Data!$W$2:$W$60,0))&" / "&INDEX(Data!$R$2:$R$60,MATCH(8,Data!$W$2:$W$60,0)),"")
B20: =IFERROR(INDEX(Data!$K$2:$K$60,MATCH(9,Data!$W$2:$W$60,0)),"") | C20: =IFERROR(INDEX(Data!$D$2:$D$60,MATCH(9,Data!$W$2:$W$60,0)),"") | D20: =IFERROR(INDEX(Data!$B$2:$B$60,MATCH(9,Data!$W$2:$W$60,0)),"") | E20: =IFERROR(INDEX(Data!$C$2:$C$60,MATCH(9,Data!$W$2:$W$60,0)),"") | F20: =IFERROR(INDEX(Data!$G$2:$G$60,MATCH(9,Data!$W$2:$W$60,0)),"") | G20: =IFERROR(INDEX(Data!$V$2:$V$60,MATCH(9,Data!$W$2:$W$60,0)),"") | H20: =IFERROR(INDEX(Data!$O$2:$O$60,MATCH(9,Data!$W$2:$W$60,0))&" / "&INDEX(Data!$R$2:$R$60,MATCH(9,Data!$W$2:$W$60,0)),"")
B21: =IFERROR(INDEX(Data!$K$2:$K$60,MATCH(10,Data!$W$2:$W$60,0)),"") | C21: =IFERROR(INDEX(Data!$D$2:$D$60,MATCH(10,Data!$W$2:$W$60,0)),"") | D21: =IFERROR(INDEX(Data!$B$2:$B$60,MATCH(10,Data!$W$2:$W$60,0)),"") | E21: =IFERROR(INDEX(Data!$C$2:$C$60,MATCH(10,Data!$W$2:$W$60,0)),"") | F21: =IFERROR(INDEX(Data!$G$2:$G$60,MATCH(10,Data!$W$2:$W$60,0)),"") | G21: =IFERROR(INDEX(Data!$V$2:$V$60,MATCH(10,Data!$W$2:$W$60,0)),"") | H21: =IFERROR(INDEX(Data!$O$2:$O$60,MATCH(10,Data!$W$2:$W$60,0))&" / "&INDEX(Data!$R$2:$R$60,MATCH(10,Data!$W$2:$W$60,0)),"")
B22: =IFERROR(INDEX(Data!$K$2:$K$60,MATCH(11,Data!$W$2:$W$60,0)),"") | C22: =IFERROR(INDEX(Data!$D$2:$D$60,MATCH(11,Data!$W$2:$W$60,0)),"") | D22: =IFERROR(INDEX(Data!$B$2:$B$60,MATCH(11,Data!$W$2:$W$60,0)),"") | E22: =IFERROR(INDEX(Data!$C$2:$C$60,MATCH(11,Data!$W$2:$W$60,0)),"") | F22: =IFERROR(INDEX(Data!$G$2:$G$60,MATCH(11,Data!$W$2:$W$60,0)),"") | G22: =IFERROR(INDEX(Data!$V$2:$V$60,MATCH(11,Data!$W$2:$W$60,0)),"") | H22: =IFERROR(INDEX(Data!$O$2:$O$60,MATCH(11,Data!$W$2:$W$60,0))&" / "&INDEX(Data!$R$2:$R$60,MATCH(11,Data!$W$2:$W$60,0)),"")
B23: =IFERROR(INDEX(Data!$K$2:$K$60,MATCH(12,Data!$W$2:$W$60,0)),"") | C23: =IFERROR(INDEX(Data!$D$2:$D$60,MATCH(12,Data!$W$2:$W$60,0)),"") | D23: =IFERROR(INDEX(Data!$B$2:$B$60,MATCH(12,Data!$W$2:$W$60,0)),"") | E23: =IFERROR(INDEX(Data!$C$2:$C$60,MATCH(12,Data!$W$2:$W$60,0)),"") | F23: =IFERROR(INDEX(Data!$G$2:$G$60,MATCH(12,Data!$W$2:$W$60,0)),"") | G23: =IFERROR(INDEX(Data!$V$2:$V$60,MATCH(12,Data!$W$2:$W$60,0)),"") | H23: =IFERROR(INDEX(Data!$O$2:$O$60,MATCH(12,Data!$W$2:$W$60,0))&" / "&INDEX(Data!$R$2:$R$60,MATCH(12,Data!$W$2:$W$60,0)),"")
B24: =IFERROR(INDEX(Data!$K$2:$K$60,MATCH(13,Data!$W$2:$W$60,0)),"") | C24: =IFERROR(INDEX(Data!$D$2:$D$60,MATCH(13,Data!$W$2:$W$60,0)),"") | D24: =IFERROR(INDEX(Data!$B$2:$B$60,MATCH(13,Data!$W$2:$W$60,0)),"") | E24: =IFERROR(INDEX(Data!$C$2:$C$60,MATCH(13,Data!$W$2:$W$60,0)),"") | F24: =IFERROR(INDEX(Data!$G$2:$G$60,MATCH(13,Data!$W$2:$W$60,0)),"") | G24: =IFERROR(INDEX(Data!$V$2:$V$60,MATCH(13,Data!$W$2:$W$60,0)),"") | H24: =IFERROR(INDEX(Data!$O$2:$O$60,MATCH(13,Data!$W$2:$W$60,0))&" / "&INDEX(Data!$R$2:$R$60,MATCH(13,Data!$W$2:$W$60,0)),"")
B25: =IFERROR(INDEX(Data!$K$2:$K$60,MATCH(14,Data!$W$2:$W$60,0)),"") | C25: =IFERROR(INDEX(Data!$D$2:$D$60,MATCH(14,Data!$W$2:$W$60,0)),"") | D25: =IFERROR(INDEX(Data!$B$2:$B$60,MATCH(14,Data!$W$2:$W$60,0)),"") | E25: =IFERROR(INDEX(Data!$C$2:$C$60,MATCH(14,Data!$W$2:$W$60,0)),"") | F25: =IFERROR(INDEX(Data!$G$2:$G$60,MATCH(14,Data!$W$2:$W$60,0)),"") | G25: =IFERROR(INDEX(Data!$V$2:$V$60,MATCH(14,Data!$W$2:$W$60,0)),"") | H25: =IFERROR(INDEX(Data!$O$2:$O$60,MATCH(14,Data!$W$2:$W$60,0))&" / "&INDEX(Data!$R$2:$R$60,MATCH(14,Data!$W$2:$W$60,0)),"")
B26: =IFERROR(INDEX(Data!$K$2:$K$60,MATCH(15,Data!$W$2:$W$60,0)),"") | C26: =IFERROR(INDEX(Data!$D$2:$D$60,MATCH(15,Data!$W$2:$W$60,0)),"") | D26: =IFERROR(INDEX(Data!$B$2:$B$60,MATCH(15,Data!$W$2:$W$60,0)),"") | E26: =IFERROR(INDEX(Data!$C$2:$C$60,MATCH(15,Data!$W$2:$W$60,0)),"") | F26: =IFERROR(INDEX(Data!$G$2:$G$60,MATCH(15,Data!$W$2:$W$60,0)),"") | G26: =IFERROR(INDEX(Data!$V$2:$V$60,MATCH(15,Data!$W$2:$W$60,0)),"") | H26: =IFERROR(INDEX(Data!$O$2:$O$60,MATCH(15,Data!$W$2:$W$60,0))&" / "&INDEX(Data!$R$2:$R$60,MATCH(15,Data!$W$2:$W$60,0)),"")
B27: =IFERROR(INDEX(Data!$K$2:$K$60,MATCH(16,Data!$W$2:$W$60,0)),"") | C27: =IFERROR(INDEX(Data!$D$2:$D$60,MATCH(16,Data!$W$2:$W$60,0)),"") | D27: =IFERROR(INDEX(Data!$B$2:$B$60,MATCH(16,Data!$W$2:$W$60,0)),"") | E27: =IFERROR(INDEX(Data!$C$2:$C$60,MATCH(16,Data!$W$2:$W$60,0)),"") | F27: =IFERROR(INDEX(Data!$G$2:$G$60,MATCH(16,Data!$W$2:$W$60,0)),"") | G27: =IFERROR(INDEX(Data!$V$2:$V$60,MATCH(16,Data!$W$2:$W$60,0)),"") | H27: =IFERROR(INDEX(Data!$O$2:$O$60,MATCH(16,Data!$W$2:$W$60,0))&" / "&INDEX(Data!$R$2:$R$60,MATCH(16,Data!$W$2:$W$60,0)),"")
B28: =IFERROR(INDEX(Data!$K$2:$K$60,MATCH(17,Data!$W$2:$W$60,0)),"") | C28: =IFERROR(INDEX(Data!$D$2:$D$60,MATCH(17,Data!$W$2:$W$60,0)),"") | D28: =IFERROR(INDEX(Data!$B$2:$B$60,MATCH(17,Data!$W$2:$W$60,0)),"") | E28: =IFERROR(INDEX(Data!$C$2:$C$60,MATCH(17,Data!$W$2:$W$60,0)),"") | F28: =IFERROR(INDEX(Data!$G$2:$G$60,MATCH(17,Data!$W$2:$W$60,0)),"") | G28: =IFERROR(INDEX(Data!$V$2:$V$60,MATCH(17,Data!$W$2:$W$60,0)),"") | H28: =IFERROR(INDEX(Data!$O$2:$O$60,MATCH(17,Data!$W$2:$W$60,0))&" / "&INDEX(Data!$R$2:$R$60,MATCH(17,Data!$W$2:$W$60,0)),"")
B29: =IFERROR(INDEX(Data!$K$2:$K$60,MATCH(18,Data!$W$2:$W$60,0)),"") | C29: =IFERROR(INDEX(Data!$D$2:$D$60,MATCH(18,Data!$W$2:$W$60,0)),"") | D29: =IFERROR(INDEX(Data!$B$2:$B$60,MATCH(18,Data!$W$2:$W$60,0)),"") | E29: =IFERROR(INDEX(Data!$C$2:$C$60,MATCH(18,Data!$W$2:$W$60,0)),"") | F29: =IFERROR(INDEX(Data!$G$2:$G$60,MATCH(18,Data!$W$2:$W$60,0)),"") | G29: =IFERROR(INDEX(Data!$V$2:$V$60,MATCH(18,Data!$W$2:$W$60,0)),"") | H29: =IFERROR(INDEX(Data!$O$2:$O$60,MATCH(18,Data!$W$2:$W$60,0))&" / "&INDEX(Data!$R$2:$R$60,MATCH(18,Data!$W$2:$W$60,0)),"")
B30: =IFERROR(INDEX(Data!$K$2:$K$60,MATCH(19,Data!$W$2:$W$60,0)),"") | C30: =IFERROR(INDEX(Data!$D$2:$D$60,MATCH(19,Data!$W$2:$W$60,0)),"") | D30: =IFERROR(INDEX(Data!$B$2:$B$60,MATCH(19,Data!$W$2:$W$60,0)),"") | E30: =IFERROR(INDEX(Data!$C$2:$C$60,MATCH(19,Data!$W$2:$W$60,0)),"") | F30: =IFERROR(INDEX(Data!$G$2:$G$60,MATCH(19,Data!$W$2:$W$60,0)),"") | G30: =IFERROR(INDEX(Data!$V$2:$V$60,MATCH(19,Data!$W$2:$W$60,0)),"") | H30: =IFERROR(INDEX(Data!$O$2:$O$60,MATCH(19,Data!$W$2:$W$60,0))&" / "&INDEX(Data!$R$2:$R$60,MATCH(19,Data!$W$2:$W$60,0)),"")
B31: =IFERROR(INDEX(Data!$K$2:$K$60,MATCH(20,Data!$W$2:$W$60,0)),"") | C31: =IFERROR(INDEX(Data!$D$2:$D$60,MATCH(20,Data!$W$2:$W$60,0)),"") | D31: =IFERROR(INDEX(Data!$B$2:$B$60,MATCH(20,Data!$W$2:$W$60,0)),"") | E31: =IFERROR(INDEX(Data!$C$2:$C$60,MATCH(20,Data!$W$2:$W$60,0)),"") | F31: =IFERROR(INDEX(Data!$G$2:$G$60,MATCH(20,Data!$W$2:$W$60,0)),"") | G31: =IFERROR(INDEX(Data!$V$2:$V$60,MATCH(20,Data!$W$2:$W$60,0)),"") | H31: =IFERROR(INDEX(Data!$O$2:$O$60,MATCH(20,Data!$W$2:$W$60,0))&" / "&INDEX(Data!$R$2:$R$60,MATCH(20,Data!$W$2:$W$60,0)),"")

Sheet Data
A1: ID | B1: Make | C1: Model | D1: Year | E1: Type | F1: Status | G1: Buy Price | H1: Sell Price | I1: Profit | J1: Days to Sell | K1: Purchase Date | L1: Sale Date | M1: Sold To | N1: Buyer Contact | O1: Partner 1 | P1: P1 Cash | Q1: P1 % | R1: Partner 2 | S1: P2 Cash | T1: P2 % | U1: Sale Month | V1: Days Held | W1: InvSeq | Y1: ◄ Update vehicles here. Sell Price + Sale Date = SOLD. Partner cash defaults to half the buy price (50/50 Zeshan/Asmaar); change a cash amount and the % recalculates.
A2: 1 | B2: Kawasaki | C2: Ninja 300 | D2: 2014 | E2: Motorcycle | F2: =IF($B2="","",IF($H2="","In Inventory","Sold")) -> In Inventory | G2: 2500 | I2: =IF(OR($B2="",$H2=""),"",$H2-$G2) | J2: =IF(OR($H2="",$L2="",$K2=""),"",$L2-$K2) | K2: 46176 | O2: Zeshan | P2: =IF($B2="","",$G2/2) -> 1250 | Q2: =IF($B2="","",IFERROR(N($P2)/(N($P2)+N($S2)),"")) -> 0.5 | R2: Asmaar | S2: =IF($B2="","",$G2/2) -> 1250 | T2: =IF($B2="","",IFERROR(N($S2)/(N($P2)+N($S2)),"")) -> 0.5 | U2: =IF($L2="","",TEXT($L2,"YYYY-MM")) | V2: =IF(OR($B2="",$H2<>""),"",TODAY()-$K2) -> 9 | W2: =IF($F2="In Inventory",COUNTIF($F$2:$F2,"In Inventory"),"") -> 1
A3: 2 | B3: Kawasaki | C3: Ninja 300 | D3: 2015 | E3: Motorcycle | F3: =IF($B3="","",IF($H3="","In Inventory","Sold")) -> In Inventory | G3: 2400 | I3: =IF(OR($B3="",$H3=""),"",$H3-$G3) | J3: =IF(OR($H3="",$L3="",$K3=""),"",$L3-$K3) | K3: 46158 | O3: Zeshan | P3: =IF($B3="","",$G3/2) -> 1200 | Q3: =IF($B3="","",IFERROR(N($P3)/(N($P3)+N($S3)),"")) -> 0.5 | R3: Asmaar | S3: =IF($B3="","",$G3/2) -> 1200 | T3: =IF($B3="","",IFERROR(N($S3)/(N($P3)+N($S3)),"")) -> 0.5 | U3: =IF($L3="","",TEXT($L3,"YYYY-MM")) | V3: =IF(OR($B3="",$H3<>""),"",TODAY()-$K3) -> 27 | W3: =IF($F3="In Inventory",COUNTIF($F$2:$F3,"In Inventory"),"") -> 2
A4: 3 | B4: Kawasaki | C4: Ninja 650 | D4: 2021 | E4: Motorcycle | F4: =IF($B4="","",IF($H4="","In Inventory","Sold")) -> In Inventory | G4: 4800 | I4: =IF(OR($B4="",$H4=""),"",$H4-$G4) | J4: =IF(OR($H4="",$L4="",$K4=""),"",$L4-$K4) | K4: 46151 | O4: Zeshan | P4: =IF($B4="","",$G4/2) -> 2400 | Q4: =IF($B4="","",IFERROR(N($P4)/(N($P4)+N($S4)),"")) -> 0.5 | R4: Asmaar | S4: =IF($B4="","",$G4/2) -> 2400 | T4: =IF($B4="","",IFERROR(N($S4)/(N($P4)+N($S4)),"")) -> 0.5 | U4: =IF($L4="","",TEXT($L4,"YYYY-MM")) | V4: =IF(OR($B4="",$H4<>""),"",TODAY()-$K4) -> 34 | W4: =IF($F4="In Inventory",COUNTIF($F$2:$F4,"In Inventory"),"") -> 3
A5: 4 | B5: Kawasaki | C5: ZX-6R | D5: 2024 | E5: Motorcycle | F5: =IF($B5="","",IF($H5="","In Inventory","Sold")) -> Sold | G5: 8500 | H5: 9400 | I5: =IF(OR($B5="",$H5=""),"",$H5-$G5) -> 900 | J5: =IF(OR($H5="",$L5="",$K5=""),"",$L5-$K5) -> 18 | K5: 46144 | L5: 46162 | O5: Zeshan | P5: =IF($B5="","",$G5/2) -> 4250 | Q5: =IF($B5="","",IFERROR(N($P5)/(N($P5)+N($S5)),"")) -> 0.5 | R5: Asmaar | S5: =IF($B5="","",$G5/2) -> 4250 | T5: =IF($B5="","",IFERROR(N($S5)/(N($P5)+N($S5)),"")) -> 0.5 | U5: =IF($L5="","",TEXT($L5,"YYYY-MM")) -> 2026-05 | V5: =IF(OR($B5="",$H5<>""),"",TODAY()-$K5) | W5: =IF($F5="In Inventory",COUNTIF($F$2:$F5,"In Inventory"),"")
A6: 5 | B6: Yamaha | C6: YZF-R3 | D6: 2015 | E6: Motorcycle | F6: =IF($B6="","",IF($H6="","In Inventory","Sold")) -> In Inventory | G6: 2500 | I6: =IF(OR($B6="",$H6=""),"",$H6-$G6) | J6: =IF(OR($H6="",$L6="",$K6=""),"",$L6-$K6) | K6: 46132 | O6: Zeshan | P6: =IF($B6="","",$G6/2) -> 1250 | Q6: =IF($B6="","",IFERROR(N($P6)/(N($P6)+N($S6)),"")) -> 0.5 | R6: Asmaar | S6: =IF($B6="","",$G6/2) -> 1250 | T6: =IF($B6="","",IFERROR(N($S6)/(N($P6)+N($S6)),"")) -> 0.5 | U6: =IF($L6="","",TEXT($L6,"YYYY-MM")) | V6: =IF(OR($B6="",$H6<>""),"",TODAY()-$K6) -> 53 | W6: =IF($F6="In Inventory",COUNTIF($F$2:$F6,"In Inventory"),"") -> 4
A7: 6 | B7: Yamaha | C7: YZF-R3 | D7: 2024 | E7: Motorcycle | F7: =IF($B7="","",IF($H7="","In Inventory","Sold")) -> Sold | G7: 3700 | H7: 4600 | I7: =IF(OR($B7="",$H7=""),"",$H7-$G7) -> 900 | J7: =IF(OR($H7="",$L7="",$K7=""),"",$L7-$K7) -> 12 | K7: 46124 | L7: 46136 | O7: Zeshan | P7: =IF($B7="","",$G7/2) -> 1850 | Q7: =IF($B7="","",IFERROR(N($P7)/(N($P7)+N($S7)),"")) -> 0.5 | R7: Asmaar | S7: =IF($B7="","",$G7/2) -> 1850 | T7: =IF($B7="","",IFERROR(N($S7)/(N($P7)+N($S7)),"")) -> 0.5 | U7: =IF($L7="","",TEXT($L7,"YYYY-MM")) -> 2026-04 | V7: =IF(OR($B7="",$H7<>""),"",TODAY()-$K7) | W7: =IF($F7="In Inventory",COUNTIF($F$2:$F7,"In Inventory"),"")
A8: 7 | B8: Kawasaki | C8: Ninja 300 | D8: 2015 | E8: Motorcycle | F8: =IF($B8="","",IF($H8="","In Inventory","Sold")) -> Sold | G8: 2600 | H8: 3600 | I8: =IF(OR($B8="",$H8=""),"",$H8-$G8) -> 1000 | J8: =IF(OR($H8="",$L8="",$K8=""),"",$L8-$K8) -> 10 | K8: 46116 | L8: 46126 | O8: Zeshan | P8: =IF($B8="","",$G8/2) -> 1300 | Q8: =IF($B8="","",IFERROR(N($P8)/(N($P8)+N($S8)),"")) -> 0.5 | R8: Asmaar | S8: =IF($B8="","",$G8/2) -> 1300 | T8: =IF($B8="","",IFERROR(N($S8)/(N($P8)+N($S8)),"")) -> 0.5 | U8: =IF($L8="","",TEXT($L8,"YYYY-MM")) -> 2026-04 | V8: =IF(OR($B8="",$H8<>""),"",TODAY()-$K8) | W8: =IF($F8="In Inventory",COUNTIF($F$2:$F8,"In Inventory"),"")
A9: 8 | B9: CFMoto | C9: 300SS | D9: 2023 | E9: Motorcycle | F9: =IF($B9="","",IF($H9="","In Inventory","Sold")) -> Sold | G9: 2400 | H9: 3200 | I9: =IF(OR($B9="",$H9=""),"",$H9-$G9) -> 800 | J9: =IF(OR($H9="",$L9="",$K9=""),"",$L9-$K9) -> 13 | K9: 46105 | L9: 46118 | O9: Zeshan | P9: =IF($B9="","",$G9/2) -> 1200 | Q9: =IF($B9="","",IFERROR(N($P9)/(N($P9)+N($S9)),"")) -> 0.5 | R9: Asmaar | S9: =IF($B9="","",$G9/2) -> 1200 | T9: =IF($B9="","",IFERROR(N($S9)/(N($P9)+N($S9)),"")) -> 0.5 | U9: =IF($L9="","",TEXT($L9,"YYYY-MM")) -> 2026-04 | V9: =IF(OR($B9="",$H9<>""),"",TODAY()-$K9) | W9: =IF($F9="In Inventory",COUNTIF($F$2:$F9,"In Inventory"),"")
A10: 9 | B10: Kawasaki | C10: Ninja 500 | D10: 2025 | E10: Motorcycle | F10: =IF($B10="","",IF($H10="","In Inventory","Sold")) -> Sold | G10: 4100 | H10: 5000 | I10: =IF(OR($B10="",$H10=""),"",$H10-$G10) -> 900 | J10: =IF(OR($H10="",$L10="",$K10=""),"",$L10-$K10) -> 11 | K10: 46096 | L10: 46107 | O10: Zeshan | P10: =IF($B10="","",$G10/2) -> 2050 | Q10: =IF($B10="","",IFERROR(N($P10)/(N($P10)+N($S10)),"")) -> 0.5 | R10: Asmaar | S10: =IF($B10="","",$G10/2) -> 2050 | T10: =IF($B10="","",IFERROR(N($S10)/(N($P10)+N($S10)),"")) -> 0.5 | U10: =IF($L10="","",TEXT($L10,"YYYY-MM")) -> 2026-03 | V10: =IF(OR($B10="",$H10<>""),"",TODAY()-$K10) | W10: =IF($F10="In Inventory",COUNTIF($F$2:$F10,"In Inventory"),"")
A11: 10 | B11: Kawasaki | C11: Ninja 650 | D11: 2019 | E11: Motorcycle | F11: =IF($B11="","",IF($H11="","In Inventory","Sold")) -> Sold | G11: 2800 | H11: 4000 | I11: =IF(OR($B11="",$H11=""),"",$H11-$G11) -> 1200 | J11: =IF(OR($H11="",$L11="",$K11=""),"",$L11-$K11) -> 16 | K11: 46089 | L11: 46105 | O11: Zeshan | P11: =IF($B11="","",$G11/2) -> 1400 | Q11: =IF($B11="","",IFERROR(N($P11)/(N($P11)+N($S11)),"")) -> 0.5 | R11: Asmaar | S11: =IF($B11="","",$G11/2) -> 1400 | T11: =IF($B11="","",IFERROR(N($S11)/(N($P11)+N($S11)),"")) -> 0.5 | U11: =IF($L11="","",TEXT($L11,"YYYY-MM")) -> 2026-03 | V11: =IF(OR($B11="",$H11<>""),"",TODAY()-$K11) | W11: =IF($F11="In Inventory",COUNTIF($F$2:$F11,"In Inventory"),"")
A12: 11 | B12: Kawasaki | C12: Ninja 400 | D12: 2021 | E12: Motorcycle | F12: =IF($B12="","",IF($H12="","In Inventory","Sold")) -> Sold | G12: 3500 | H12: 4250 | I12: =IF(OR($B12="",$H12=""),"",$H12-$G12) -> 750 | J12: =IF(OR($H12="",$L12="",$K12=""),"",$L12-$K12) -> 9 | K12: 46084 | L12: 46093 | O12: Zeshan | P12: =IF($B12="","",$G12/2) -> 1750 | Q12: =IF($B12="","",IFERROR(N($P12)/(N($P12)+N($S12)),"")) -> 0.5 | R12: Asmaar | S12: =IF($B12="","",$G12/2) -> 1750 | T12: =IF($B12="","",IFERROR(N($S12)/(N($P12)+N($S12)),"")) -> 0.5 | U12: =IF($L12="","",TEXT($L12,"YYYY-MM")) -> 2026-03 | V12: =IF(OR($B12="",$H12<>""),"",TODAY()-$K12) | W12: =IF($F12="In Inventory",COUNTIF($F$2:$F12,"In Inventory"),"")
A13: 12 | B13: Kawasaki | C13: Ninja 400 | D13: 2023 | E13: Motorcycle | F13: =IF($B13="","",IF($H13="","In Inventory","Sold")) -> Sold | G13: 3400 | H13: 4000 | I13: =IF(OR($B13="",$H13=""),"",$H13-$G13) -> 600 | J13: =IF(OR($H13="",$L13="",$K13=""),"",$L13-$K13) -> 14 | K13: 46071 | L13: 46085 | O13: Zeshan | P13: =IF($B13="","",$G13/2) -> 1700 | Q13: =IF($B13="","",IFERROR(N($P13)/(N($P13)+N($S13)),"")) -> 0.5 | R13: Asmaar | S13: =IF($B13="","",$G13/2) -> 1700 | T13: =IF($B13="","",IFERROR(N($S13)/(N($P13)+N($S13)),"")) -> 0.5 | U13: =IF($L13="","",TEXT($L13,"YYYY-MM")) -> 2026-03 | V13: =IF(OR($B13="",$H13<>""),"",TODAY()-$K13) | W13: =IF($F13="In Inventory",COUNTIF($F$2:$F13,"In Inventory"),"")
A14: 13 | B14: Honda | C14: CBR500R | D14: 2017 | E14: Motorcycle | F14: =IF($B14="","",IF($H14="","In Inventory","Sold")) -> Sold | G14: 3700 | H14: 4200 | I14: =IF(OR($B14="",$H14=""),"",$H14-$G14) -> 500 | J14: =IF(OR($H14="",$L14="",$K14=""),"",$L14-$K14) -> 22 | K14: 46058 | L14: 46080 | O14: Zeshan | P14: =IF($B14="","",$G14/2) -> 1850 | Q14: =IF($B14="","",IFERROR(N($P14)/(N($P14)+N($S14)),"")) -> 0.5 | R14: Asmaar | S14: =IF($B14="","",$G14/2) -> 1850 | T14: =IF($B14="","",IFERROR(N($S14)/(N($P14)+N($S14)),"")) -> 0.5 | U14: =IF($L14="","",TEXT($L14,"YYYY-MM")) -> 2026-02 | V14: =IF(OR($B14="",$H14<>""),"",TODAY()-$K14) | W14: =IF($F14="In Inventory",COUNTIF($F$2:$F14,"In Inventory"),"")
A15: 14 | B15: Kawasaki | C15: Ninja 500 | D15: 2024 | E15: Motorcycle | F15: =IF($B15="","",IF($H15="","In Inventory","Sold")) -> Sold | G15: 4000 | H15: 4750 | I15: =IF(OR($B15="",$H15=""),"",$H15-$G15) -> 750 | J15: =IF(OR($H15="",$L15="",$K15=""),"",$L15-$K15) -> 12 | K15: 45970 | L15: 45982 | O15: Zeshan | P15: =IF($B15="","",$G15/2) -> 2000 | Q15: =IF($B15="","",IFERROR(N($P15)/(N($P15)+N($S15)),"")) -> 0.5 | R15: Asmaar | S15: =IF($B15="","",$G15/2) -> 2000 | T15: =IF($B15="","",IFERROR(N($S15)/(N($P15)+N($S15)),"")) -> 0.5 | U15: =IF($L15="","",TEXT($L15,"YYYY-MM")) -> 2025-11 | V15: =IF(OR($B15="",$H15<>""),"",TODAY()-$K15) | W15: =IF($F15="In Inventory",COUNTIF($F$2:$F15,"In Inventory"),"")
A16: 15 | B16: Ducati | C16: Monster 696 | D16: 2009 | E16: Motorcycle | F16: =IF($B16="","",IF($H16="","In Inventory","Sold")) -> Sold | G16: 3000 | H16: 3200 | I16: =IF(OR($B16="",$H16=""),"",$H16-$G16) -> 200 | J16: =IF(OR($H16="",$L16="",$K16=""),"",$L16-$K16) -> 28 | K16: 45936 | L16: 45964 | O16: Zeshan | P16: =IF($B16="","",$G16/2) -> 1500 | Q16: =IF($B16="","",IFERROR(N($P16)/(N($P16)+N($S16)),"")) -> 0.5 | R16: Asmaar | S16: =IF($B16="","",$G16/2) -> 1500 | T16: =IF($B16="","",IFERROR(N($S16)/(N($P16)+N($S16)),"")) -> 0.5 | U16: =IF($L16="","",TEXT($L16,"YYYY-MM")) -> 2025-11 | V16: =IF(OR($B16="",$H16<>""),"",TODAY()-$K16) | W16: =IF($F16="In Inventory",COUNTIF($F$2:$F16,"In Inventory"),"")
A17: 16 | B17: Kawasaki | C17: Ninja 400 | D17: 2023 | E17: Motorcycle | F17: =IF($B17="","",IF($H17="","In Inventory","Sold")) -> Sold | G17: 4000 | H17: 4900 | I17: =IF(OR($B17="",$H17=""),"",$H17-$G17) -> 900 | J17: =IF(OR($H17="",$L17="",$K17=""),"",$L17-$K17) -> 15 | K17: 45922 | L17: 45937 | O17: Zeshan | P17: =IF($B17="","",$G17/2) -> 2000 | Q17: =IF($B17="","",IFERROR(N($P17)/(N($P17)+N($S17)),"")) -> 0.5 | R17: Asmaar | S17: =IF($B17="","",$G17/2) -> 2000 | T17: =IF($B17="","",IFERROR(N($S17)/(N($P17)+N($S17)),"")) -> 0.5 | U17: =IF($L17="","",TEXT($L17,"YYYY-MM")) -> 2025-10 | V17: =IF(OR($B17="",$H17<>""),"",TODAY()-$K17) | W17: =IF($F17="In Inventory",COUNTIF($F$2:$F17,"In Inventory"),"")
A18: 17 | B18: Kawasaki | C18: Ninja 500 | D18: 2025 | E18: Motorcycle | F18: =IF($B18="","",IF($H18="","In Inventory","Sold")) -> Sold | G18: 4350 | H18: 4900 | I18: =IF(OR($B18="",$H18=""),"",$H18-$G18) -> 550 | J18: =IF(OR($H18="",$L18="",$K18=""),"",$L18-$K18) -> 10 | K18: 45914 | L18: 45924 | O18: Zeshan | P18: =IF($B18="","",$G18/2) -> 2175 | Q18: =IF($B18="","",IFERROR(N($P18)/(N($P18)+N($S18)),"")) -> 0.5 | R18: Asmaar | S18: =IF($B18="","",$G18/2) -> 2175 | T18: =IF($B18="","",IFERROR(N($S18)/(N($P18)+N($S18)),"")) -> 0.5 | U18: =IF($L18="","",TEXT($L18,"YYYY-MM")) -> 2025-09 | V18: =IF(OR($B18="",$H18<>""),"",TODAY()-$K18) | W18: =IF($F18="In Inventory",COUNTIF($F$2:$F18,"In Inventory"),"")
A19: 18 | B19: Toyota | C19: Camry | D19: 2009 | E19: Car | F19: =IF($B19="","",IF($H19="","In Inventory","Sold")) -> In Inventory | G19: 3200 | I19: =IF(OR($B19="",$H19=""),"",$H19-$G19) | J19: =IF(OR($H19="",$L19="",$K19=""),"",$L19-$K19) | K19: 45908 | O19: Zeshan | P19: =IF($B19="","",$G19/2) -> 1600 | Q19: =IF($B19="","",IFERROR(N($P19)/(N($P19)+N($S19)),"")) -> 0.5 | R19: Asmaar | S19: =IF($B19="","",$G19/2) -> 1600 | T19: =IF($B19="","",IFERROR(N($S19)/(N($P19)+N($S19)),"")) -> 0.5 | U19: =IF($L19="","",TEXT($L19,"YYYY-MM")) | V19: =IF(OR($B19="",$H19<>""),"",TODAY()-$K19) -> 277 | W19: =IF($F19="In Inventory",COUNTIF($F$2:$F19,"In Inventory"),"") -> 5
A20: 19 | B20: Toyota | C20: Camry | D20: 2010 | E20: Car | F20: =IF($B20="","",IF($H20="","In Inventory","Sold")) -> Sold | G20: 2800 | H20: 3950 | I20: =IF(OR($B20="",$H20=""),"",$H20-$G20) -> 1150 | J20: =IF(OR($H20="",$L20="",$K20=""),"",$L20-$K20) -> 17 | K20: 45904 | L20: 45921 | O20: Zeshan | P20: =IF($B20="","",$G20/2) -> 1400 | Q20: =IF($B20="","",IFERROR(N($P20)/(N($P20)+N($S20)),"")) -> 0.5 | R20: Asmaar | S20: =IF($B20="","",$G20/2) -> 1400 | T20: =IF($B20="","",IFERROR(N($S20)/(N($P20)+N($S20)),"")) -> 0.5 | U20: =IF($L20="","",TEXT($L20,"YYYY-MM")) -> 2025-09 | V20: =IF(OR($B20="",$H20<>""),"",TODAY()-$K20) | W20: =IF($F20="In Inventory",COUNTIF($F$2:$F20,"In Inventory"),"")
A21: 20 | B21: Toyota | C21: Camry | D21: 2011 | E21: Car | F21: =IF($B21="","",IF($H21="","In Inventory","Sold")) -> Sold | G21: 3600 | H21: 4800 | I21: =IF(OR($B21="",$H21=""),"",$H21-$G21) -> 1200 | J21: =IF(OR($H21="",$L21="",$K21=""),"",$L21-$K21) -> 20 | K21: 45898 | L21: 45918 | O21: Zeshan | P21: =IF($B21="","",$G21/2) -> 1800 | Q21: =IF($B21="","",IFERROR(N($P21)/(N($P21)+N($S21)),"")) -> 0.5 | R21: Asmaar | S21: =IF($B21="","",$G21/2) -> 1800 | T21: =IF($B21="","",IFERROR(N($S21)/(N($P21)+N($S21)),"")) -> 0.5 | U21: =IF($L21="","",TEXT($L21,"YYYY-MM")) -> 2025-09 | V21: =IF(OR($B21="",$H21<>""),"",TODAY()-$K21) | W21: =IF($F21="In Inventory",COUNTIF($F$2:$F21,"In Inventory"),"")
A22: 21 | B22: Yamaha | C22: YZF-R3 | D22: 2021 | E22: Motorcycle | F22: =IF($B22="","",IF($H22="","In Inventory","Sold")) -> Sold | G22: 3500 | H22: 4900 | I22: =IF(OR($B22="",$H22=""),"",$H22-$G22) -> 1400 | J22: =IF(OR($H22="",$L22="",$K22=""),"",$L22-$K22) -> 13 | K22: 45896 | L22: 45909 | O22: Zeshan | P22: =IF($B22="","",$G22/2) -> 1750 | Q22: =IF($B22="","",IFERROR(N($P22)/(N($P22)+N($S22)),"")) -> 0.5 | R22: Asmaar | S22: =IF($B22="","",$G22/2) -> 1750 | T22: =IF($B22="","",IFERROR(N($S22)/(N($P22)+N($S22)),"")) -> 0.5 | U22: =IF($L22="","",TEXT($L22,"YYYY-MM")) -> 2025-09 | V22: =IF(OR($B22="",$H22<>""),"",TODAY()-$K22) | W22: =IF($F22="In Inventory",COUNTIF($F$2:$F22,"In Inventory"),"")
A23: 22 | B23: Kawasaki | C23: Ninja 400 | D23: 2021 | E23: Motorcycle | F23: =IF($B23="","",IF($H23="","In Inventory","Sold")) -> Sold | G23: 4000 | H23: 5250 | I23: =IF(OR($B23="",$H23=""),"",$H23-$G23) -> 1250 | J23: =IF(OR($H23="",$L23="",$K23=""),"",$L23-$K23) -> 7 | K23: 45893 | L23: 45900 | O23: Zeshan | P23: =IF($B23="","",$G23/2) -> 2000 | Q23: =IF($B23="","",IFERROR(N($P23)/(N($P23)+N($S23)),"")) -> 0.5 | R23: Asmaar | S23: =IF($B23="","",$G23/2) -> 2000 | T23: =IF($B23="","",IFERROR(N($S23)/(N($P23)+N($S23)),"")) -> 0.5 | U23: =IF($L23="","",TEXT($L23,"YYYY-MM")) -> 2025-08 | V23: =IF(OR($B23="",$H23<>""),"",TODAY()-$K23) | W23: =IF($F23="In Inventory",COUNTIF($F$2:$F23,"In Inventory"),"")
A24: 23 | B24: Yamaha | C24: YZF-R3 | D24: 2015 | E24: Motorcycle | F24: =IF($B24="","",IF($H24="","In Inventory","Sold")) -> Sold | G24: 3000 | H24: 3900 | I24: =IF(OR($B24="",$H24=""),"",$H24-$G24) -> 900 | J24: =IF(OR($H24="",$L24="",$K24=""),"",$L24-$K24) -> 18 | K24: 45889 | L24: 45907 | O24: Zeshan | P24: =IF($B24="","",$G24/2) -> 1500 | Q24: =IF($B24="","",IFERROR(N($P24)/(N($P24)+N($S24)),"")) -> 0.5 | R24: Asmaar | S24: =IF($B24="","",$G24/2) -> 1500 | T24: =IF($B24="","",IFERROR(N($S24)/(N($P24)+N($S24)),"")) -> 0.5 | U24: =IF($L24="","",TEXT($L24,"YYYY-MM")) -> 2025-09 | V24: =IF(OR($B24="",$H24<>""),"",TODAY()-$K24) | W24: =IF($F24="In Inventory",COUNTIF($F$2:$F24,"In Inventory"),"")
A25: 24 | B25: Kawasaki | C25: Ninja 400 | D25: 2020 | E25: Motorcycle | F25: =IF($B25="","",IF($H25="","In Inventory","Sold")) -> Sold | G25: 3350 | H25: 5100 | I25: =IF(OR($B25="",$H25=""),"",$H25-$G25) -> 1750 | J25: =IF(OR($H25="",$L25="",$K25=""),"",$L25-$K25) -> 11 | K25: 45887 | L25: 45898 | O25: Zeshan | P25: =IF($B25="","",$G25/2) -> 1675 | Q25: =IF($B25="","",IFERROR(N($P25)/(N($P25)+N($S25)),"")) -> 0.5 | R25: Asmaar | S25: =IF($B25="","",$G25/2) -> 1675 | T25: =IF($B25="","",IFERROR(N($S25)/(N($P25)+N($S25)),"")) -> 0.5 | U25: =IF($L25="","",TEXT($L25,"YYYY-MM")) -> 2025-08 | V25: =IF(OR($B25="",$H25<>""),"",TODAY()-$K25) | W25: =IF($F25="In Inventory",COUNTIF($F$2:$F25,"In Inventory"),"")
A26: 25 | B26: Kawasaki | C26: Ninja 650 | D26: 2021 | E26: Motorcycle | F26: =IF($B26="","",IF($H26="","In Inventory","Sold")) -> Sold | G26: 3000 | H26: 4725 | I26: =IF(OR($B26="",$H26=""),"",$H26-$G26) -> 1725 | J26: =IF(OR($H26="",$L26="",$K26=""),"",$L26-$K26) -> 16 | K26: 45881 | L26: 45897 | O26: Zeshan | P26: =IF($B26="","",$G26/2) -> 1500 | Q26: =IF($B26="","",IFERROR(N($P26)/(N($P26)+N($S26)),"")) -> 0.5 | R26: Asmaar | S26: =IF($B26="","",$G26/2) -> 1500 | T26: =IF($B26="","",IFERROR(N($S26)/(N($P26)+N($S26)),"")) -> 0.5 | U26: =IF($L26="","",TEXT($L26,"YYYY-MM")) -> 2025-08 | V26: =IF(OR($B26="",$H26<>""),"",TODAY()-$K26) | W26: =IF($F26="In Inventory",COUNTIF($F$2:$F26,"In Inventory"),"")
A27: 26 | B27: Kawasaki | C27: Z500 | D27: 2024 | E27: Motorcycle | F27: =IF($B27="","",IF($H27="","In Inventory","Sold")) -> Sold | G27: 4200 | H27: 5000 | I27: =IF(OR($B27="",$H27=""),"",$H27-$G27) -> 800 | J27: =IF(OR($H27="",$L27="",$K27=""),"",$L27-$K27) -> 21 | K27: 45878 | L27: 45899 | O27: Zeshan | P27: =IF($B27="","",$G27/2) -> 2100 | Q27: =IF($B27="","",IFERROR(N($P27)/(N($P27)+N($S27)),"")) -> 0.5 | R27: Asmaar | S27: =IF($B27="","",$G27/2) -> 2100 | T27: =IF($B27="","",IFERROR(N($S27)/(N($P27)+N($S27)),"")) -> 0.5 | U27: =IF($L27="","",TEXT($L27,"YYYY-MM")) -> 2025-08 | V27: =IF(OR($B27="",$H27<>""),"",TODAY()-$K27) | W27: =IF($F27="In Inventory",COUNTIF($F$2:$F27,"In Inventory"),"")
A28: 27 | B28: Kawasaki | C28: Ninja 300 | D28: 2015 | E28: Motorcycle | F28: =IF($B28="","",IF($H28="","In Inventory","Sold")) -> Sold | G28: 2500 | H28: 3600 | I28: =IF(OR($B28="",$H28=""),"",$H28-$G28) -> 1100 | J28: =IF(OR($H28="",$L28="",$K28=""),"",$L28-$K28) -> 14 | K28: 45874 | L28: 45888 | O28: Zeshan | P28: =IF($B28="","",$G28/2) -> 1250 | Q28: =IF($B28="","",IFERROR(N($P28)/(N($P28)+N($S28)),"")) -> 0.5 | R28: Asmaar | S28: =IF($B28="","",$G28/2) -> 1250 | T28: =IF($B28="","",IFERROR(N($S28)/(N($P28)+N($S28)),"")) -> 0.5 | U28: =IF($L28="","",TEXT($L28,"YYYY-MM")) -> 2025-08 | V28: =IF(OR($B28="",$H28<>""),"",TODAY()-$K28) | W28: =IF($F28="In Inventory",COUNTIF($F$2:$F28,"In Inventory"),"")
A29: 28 | B29: Kawasaki | C29: Ninja 400 | D29: 2023 | E29: Motorcycle | F29: =IF($B29="","",IF($H29="","In Inventory","Sold")) -> Sold | G29: 4000 | H29: 5150 | I29: =IF(OR($B29="",$H29=""),"",$H29-$G29) -> 1150 | J29: =IF(OR($H29="",$L29="",$K29=""),"",$L29-$K29) -> 9 | K29: 45872 | L29: 45881 | O29: Zeshan | P29: =IF($B29="","",$G29/2) -> 2000 | Q29: =IF($B29="","",IFERROR(N($P29)/(N($P29)+N($S29)),"")) -> 0.5 | R29: Asmaar | S29: =IF($B29="","",$G29/2) -> 2000 | T29: =IF($B29="","",IFERROR(N($S29)/(N($P29)+N($S29)),"")) -> 0.5 | U29: =IF($L29="","",TEXT($L29,"YYYY-MM")) -> 2025-08 | V29: =IF(OR($B29="",$H29<>""),"",TODAY()-$K29) | W29: =IF($F29="In Inventory",COUNTIF($F$2:$F29,"In Inventory"),"")
A30: 29 | B30: Kawasaki | C30: Ninja 250 | D30: 2017 | E30: Motorcycle | F30: =IF($B30="","",IF($H30="","In Inventory","Sold")) -> Sold | G30: 2500 | H30: 3400 | I30: =IF(OR($B30="",$H30=""),"",$H30-$G30) -> 900 | J30: =IF(OR($H30="",$L30="",$K30=""),"",$L30-$K30) -> 12 | K30: 45853 | L30: 45865 | O30: Zeshan | P30: =IF($B30="","",$G30/2) -> 1250 | Q30: =IF($B30="","",IFERROR(N($P30)/(N($P30)+N($S30)),"")) -> 0.5 | R30: Asmaar | S30: =IF($B30="","",$G30/2) -> 1250 | T30: =IF($B30="","",IFERROR(N($S30)/(N($P30)+N($S30)),"")) -> 0.5 | U30: =IF($L30="","",TEXT($L30,"YYYY-MM")) -> 2025-07 | V30: =IF(OR($B30="",$H30<>""),"",TODAY()-$K30) | W30: =IF($F30="In Inventory",COUNTIF($F$2:$F30,"In Inventory"),"")
A31: 30 | B31: KTM | C31: Duke 390 | D31: 2023 | E31: Motorcycle | F31: =IF($B31="","",IF($H31="","In Inventory","Sold")) -> Sold | G31: 3000 | H31: 4750 | I31: =IF(OR($B31="",$H31=""),"",$H31-$G31) -> 1750 | J31: =IF(OR($H31="",$L31="",$K31=""),"",$L31-$K31) -> 19 | K31: 45846 | L31: 45865 | O31: Zeshan | P31: =IF($B31="","",$G31/2) -> 1500 | Q31: =IF($B31="","",IFERROR(N($P31)/(N($P31)+N($S31)),"")) -> 0.5 | R31: Asmaar | S31: =IF($B31="","",$G31/2) -> 1500 | T31: =IF($B31="","",IFERROR(N($S31)/(N($P31)+N($S31)),"")) -> 0.5 | U31: =IF($L31="","",TEXT($L31,"YYYY-MM")) -> 2025-07 | V31: =IF(OR($B31="",$H31<>""),"",TODAY()-$K31) | W31: =IF($F31="In Inventory",COUNTIF($F$2:$F31,"In Inventory"),"")
F32: =IF($B32="","",IF($H32="","In Inventory","Sold")) | I32: =IF(OR($B32="",$H32=""),"",$H32-$G32) | J32: =IF(OR($H32="",$L32="",$K32=""),"",$L32-$K32) | P32: =IF($B32="","",$G32/2) | Q32: =IF($B32="","",IFERROR(N($P32)/(N($P32)+N($S32)),"")) | S32: =IF($B32="","",$G32/2) | T32: =IF($B32="","",IFERROR(N($S32)/(N($P32)+N($S32)),"")) | U32: =IF($L32="","",TEXT($L32,"YYYY-MM")) | V32: =IF(OR($B32="",$H32<>""),"",TODAY()-$K32) | W32: =IF($F32="In Inventory",COUNTIF($F$2:$F32,"In Inventory"),"")
F33: =IF($B33="","",IF($H33="","In Inventory","Sold")) | I33: =IF(OR($B33="",$H33=""),"",$H33-$G33) | J33: =IF(OR($H33="",$L33="",$K33=""),"",$L33-$K33) | P33: =IF($B33="","",$G33/2) | Q33: =IF($B33="","",IFERROR(N($P33)/(N($P33)+N($S33)),"")) | S33: =IF($B33="","",$G33/2) | T33: =IF($B33="","",IFERROR(N($S33)/(N($P33)+N($S33)),"")) | U33: =IF($L33="","",TEXT($L33,"YYYY-MM")) | V33: =IF(OR($B33="",$H33<>""),"",TODAY()-$K33) | W33: =IF($F33="In Inventory",COUNTIF($F$2:$F33,"In Inventory"),"")
F34: =IF($B34="","",IF($H34="","In Inventory","Sold")) | I34: =IF(OR($B34="",$H34=""),"",$H34-$G34) | J34: =IF(OR($H34="",$L34="",$K34=""),"",$L34-$K34) | P34: =IF($B34="","",$G34/2) | Q34: =IF($B34="","",IFERROR(N($P34)/(N($P34)+N($S34)),"")) | S34: =IF($B34="","",$G34/2) | T34: =IF($B34="","",IFERROR(N($S34)/(N($P34)+N($S34)),"")) | U34: =IF($L34="","",TEXT($L34,"YYYY-MM")) | V34: =IF(OR($B34="",$H34<>""),"",TODAY()-$K34) | W34: =IF($F34="In Inventory",COUNTIF($F$2:$F34,"In Inventory"),"")
F35: =IF($B35="","",IF($H35="","In Inventory","Sold")) | I35: =IF(OR($B35="",$H35=""),"",$H35-$G35) | J35: =IF(OR($H35="",$L35="",$K35=""),"",$L35-$K35) | P35: =IF($B35="","",$G35/2) | Q35: =IF($B35="","",IFERROR(N($P35)/(N($P35)+N($S35)),"")) | S35: =IF($B35="","",$G35/2) | T35: =IF($B35="","",IFERROR(N($S35)/(N($P35)+N($S35)),"")) | U35: =IF($L35="","",TEXT($L35,"YYYY-MM")) | V35: =IF(OR($B35="",$H35<>""),"",TODAY()-$K35) | W35: =IF($F35="In Inventory",COUNTIF($F$2:$F35,"In Inventory"),"")
F36: =IF($B36="","",IF($H36="","In Inventory","Sold")) | I36: =IF(OR($B36="",$H36=""),"",$H36-$G36) | J36: =IF(OR($H36="",$L36="",$K36=""),"",$L36-$K36) | P36: =IF($B36="","",$G36/2) | Q36: =IF($B36="","",IFERROR(N($P36)/(N($P36)+N($S36)),"")) | S36: =IF($B36="","",$G36/2) | T36: =IF($B36="","",IFERROR(N($S36)/(N($P36)+N($S36)),"")) | U36: =IF($L36="","",TEXT($L36,"YYYY-MM")) | V36: =IF(OR($B36="",$H36<>""),"",TODAY()-$K36) | W36: =IF($F36="In Inventory",COUNTIF($F$2:$F36,"In Inventory"),"")
F37: =IF($B37="","",IF($H37="","In Inventory","Sold")) | I37: =IF(OR($B37="",$H37=""),"",$H37-$G37) | J37: =IF(OR($H37="",$L37="",$K37=""),"",$L37-$K37) | P37: =IF($B37="","",$G37/2) | Q37: =IF($B37="","",IFERROR(N($P37)/(N($P37)+N($S37)),"")) | S37: =IF($B37="","",$G37/2) | T37: =IF($B37="","",IFERROR(N($S37)/(N($P37)+N($S37)),"")) | U37: =IF($L37="","",TEXT($L37,"YYYY-MM")) | V37: =IF(OR($B37="",$H37<>""),"",TODAY()-$K37) | W37: =IF($F37="In Inventory",COUNTIF($F$2:$F37,"In Inventory"),"")
F38: =IF($B38="","",IF($H38="","In Inventory","Sold")) | I38: =IF(OR($B38="",$H38=""),"",$H38-$G38) | J38: =IF(OR($H38="",$L38="",$K38=""),"",$L38-$K38) | P38: =IF($B38="","",$G38/2) | Q38: =IF($B38="","",IFERROR(N($P38)/(N($P38)+N($S38)),"")) | S38: =IF($B38="","",$G38/2) | T38: =IF($B38="","",IFERROR(N($S38)/(N($P38)+N($S38)),"")) | U38: =IF($L38="","",TEXT($L38,"YYYY-MM")) | V38: =IF(OR($B38="",$H38<>""),"",TODAY()-$K38) | W38: =IF($F38="In Inventory",COUNTIF($F$2:$F38,"In Inventory"),"")
F39: =IF($B39="","",IF($H39="","In Inventory","Sold")) | I39: =IF(OR($B39="",$H39=""),"",$H39-$G39) | J39: =IF(OR($H39="",$L39="",$K39=""),"",$L39-$K39) | P39: =IF($B39="","",$G39/2) | Q39: =IF($B39="","",IFERROR(N($P39)/(N($P39)+N($S39)),"")) | S39: =IF($B39="","",$G39/2) | T39: =IF($B39="","",IFERROR(N($S39)/(N($P39)+N($S39)),"")) | U39: =IF($L39="","",TEXT($L39,"YYYY-MM")) | V39: =IF(OR($B39="",$H39<>""),"",TODAY()-$K39) | W39: =IF($F39="In Inventory",COUNTIF($F$2:$F39,"In Inventory"),"")
F40: =IF($B40="","",IF($H40="","In Inventory","Sold")) | I40: =IF(OR($B40="",$H40=""),"",$H40-$G40) | J40: =IF(OR($H40="",$L40="",$K40=""),"",$L40-$K40) | P40: =IF($B40="","",$G40/2) | Q40: =IF($B40="","",IFERROR(N($P40)/(N($P40)+N($S40)),"")) | S40: =IF($B40="","",$G40/2) | T40: =IF($B40="","",IFERROR(N($S40)/(N($P40)+N($S40)),"")) | U40: =IF($L40="","",TEXT($L40,"YYYY-MM")) | V40: =IF(OR($B40="",$H40<>""),"",TODAY()-$K40) | W40: =IF($F40="In Inventory",COUNTIF($F$2:$F40,"In Inventory"),"")
...
